/**
 @author Alexander Vassilev
 @copyright MEGA Limited, 2014
 @license BSD 2-Clause "Simplified" License
*/

//#define TESTLOOP_LOG_DONES
//#define TESTLOOP_DEBUG
//#define TESTLOOP_DEFAULT_DONE_TIMEOUT 4000

#include <asyncTest.hpp>
#define PROMISE_ON_UNHANDLED_ERROR testUnhandledError
#include <promise.hpp>

TESTS_INIT();
using namespace promise;

std::function<void(const std::string&, int, int)> gUnhandledHandler =
[](const std::string& msg, int type, int code)
{
    printf("WARNING: Unhandled promise fail. Error: %s, type: %d, code: %d\n", msg.c_str(), type, code);
};

void testUnhandledError(const std::string& msg, int type, int code)
{
    gUnhandledHandler(msg, type, code);
}

int main()
{

TestGroup("General")
{
  asyncTest("Promise<int>: resolve->then(ret error)->fail(recover)->then",
  {{"fail", "order", 2}, {"then1", "order", 1}, {"then2", "order", 3}})
  {
      Promise<int> pms;
      pms
      .then([&](int x)->Promise<int>
      {
          doneOrError(x == 12345678, "then1");
          Promise<int> ret;
          loop.schedCall([ret]() mutable
              { ret.reject("test error message"); }, 100);
          return ret;
      })
      .fail([&](const Error& err) mutable
      {
          doneOrError(err.msg() == "test error message", "fail");
          Promise<int> ret;
          loop.schedCall([ret]() mutable
              {  ret.resolve(87654321); }, 100);
          return ret;
      })
      .then([&](int x) mutable
      {
          doneOrError(x == 87654321, "then2");
      });

      loop.schedCall([pms]() mutable
          {  pms.resolve(12345678);  }, 100);
  });

  asyncTest("Promise<void>: resolve->then(ret error)->fail(recover)->then",
  {{"fail", "order", 2}, {"then1", "order", 1}, {"then2", "order", 3}})
  {
      Promise<void> pms;
      pms
      .then([&]()
      {
          loop.done("then1");
          Promise<void> ret;
          loop.schedCall([ret]() mutable
              {  ret.reject("test error message");  }, 100);
          return ret;
      })
      .fail([&](const Error& err) mutable
      {
          doneOrError(err.msg() == "test error message", "fail");
          Promise<void> ret;
          loop.schedCall([ret]() mutable
              {  ret.resolve();  }, 100);
          return ret;
      })
      .then([&]() mutable
      {
          loop.done("then2");
      });

      loop.schedCall([pms]() mutable
          {  pms.resolve();  }, 100);
  });
  asyncTest("Rejected should skip all then()-s", {"fail1"})
  {
      Promise<void> pms;
      pms.then([&]()
      {
          test.error("then() must not be called by a rejected promise");
      })
      .then([&]()
      {
          test.error("second then() must not be called by a rejected promise");
      })
      .fail([&](const Error& err)
      {
          doneOrError(err.msg() == "test message", "fail1");
      });
      pms.reject("test message");
  });

  asyncTest("Change type", {"then1", "then2", "then-final"})
  {
      Promise<int> pms;
      pms.then([&](int a)
      {
          doneOrError(a == 1212, "then1");
      })
      .then([&]()
      {
          loop.done("then2");
          return 1;
      })
      .then([&](int a)
      {
          doneOrError(a == 1, "then-final");
      });
      pms.resolve(1212);
  });
  asyncTest("Should default-return resolved Promise<void>", {"then1", "then-final"})
  {
      Promise<int> pms;
      pms.then([&](int a) mutable
      {
          doneOrError(a == 1234, "then1");
      })
      .then([&]() mutable
      {
          test.done("then-final");
      });
      pms.resolve(1234);
  });
  asyncTest("Should propagete failure through void callback (r180f82)", {"then"})
  {
      Promise<int> pms;
      pms.then([&](int a)
      {
          return Promise<void>(Error("message"));
      })
      .then([&]() mutable
      {
          test.error("then() called by a rejected promise");
      })
      .fail([&](const Error& err) mutable
      {
          doneOrError(err.msg() == "message", "then");
      });
      loop.schedCall([pms]() mutable { pms.resolve(1); });
  });
  asyncTest("return <resolved>.then() from then() should propagate (r6f550b)")
  {
      Promise<int> pms;
      pms.then([&](int a)
      {
          Promise<int> pms1(1);
          return pms1
          .then([](int a)
          {
              return a+1;
          });
      })
      .then([&](int a)
      {
          doneOrError(a == 2, );
      });
      pms.resolve(1);

  });
  asyncTest("return <resolved>.then() from then() from then()\n      should propagate (rb1209c)")
  {
      Promise<int> pms;
      pms.then([&](int a)
      {
          Promise<int> pms1(1);
          return pms1.then([&](int a)
          {
              Promise<int> pms2(1);
              return pms2
              .then([](int a)
              {
                  return a+1;
              });
          });
      })
      .then([&](int a)
      {
          doneOrError(a == 2, );
      });
      pms.resolve(1);
  });

  asyncTest("Should propagate resolution from nested scope",
  {{"inner", "order", 1}, {"then-final", "order", 2}})
  {
      Promise<int> pms;
      pms.then([&](int a) mutable
      {
          Promise<int> pms2;
          loop.schedCall([pms2]() mutable { pms2.resolve(1234); }, 100);
          return pms2
          .then([&](int a)
          {
              Promise<int> pms3;
              loop.schedCall([pms3]() mutable { pms3.resolve(1234); }, 100);
              return pms3
              .then([&](int a)
              {
                  Promise<int> pms4;
                  loop.schedCall([pms4]() mutable { pms4.resolve(1234); }, 100);
                  return pms4
                  .then([&](int a)
                  {
                      Promise<int> pms5;
                      loop.schedCall([pms5]() mutable { pms5.resolve(1234); }, 100);
                      return pms5
                      .then([&](int a)
                      {
                          Promise<int> pms6;
                          loop.schedCall([pms6]() mutable { pms6.resolve(1234); }, 100);
                          return pms6
                          .then([&](int a)
                          {
                              test.done("inner");
                              return a+2;
                          });
                      });
                  });
              });
          });
      })
      .then([&](int a) mutable
      {
          doneOrError(a == 1236, "then-final");
      });
      pms.resolve(1);
  });
  asyncTest("Should hold the resolved value even if handlers alerady attached")
  {
     Promise<std::pair<std::string, std::string>> pms;
     pms.then([&](const std::pair<std::string, std::string>& val)
     {
         //Fix doResolve() being called with already moved value instead of
         //mSharedObj->mResult
         check(val.first == "test123");
     });
     when(pms)
     .then([&]()
     {
         //Fix resolve() calling doResolve() with the value without saving
         //the value mSharedObj->mResult. This worked before we added the value()
         //method, as the only way we could access the promise value was in
         //the .then() callbacks.
         doneOrError(pms.value().first == "test123",);
     });
     pms.resolve(std::make_pair<std::string,std::string>("test123", "fubar"));
  });
});

TestGroup("Exception tests")
{
    asyncTest("Should fail if std::exception in then() block")
    {
        Promise<int> pms;
        pms.then([&](int a)
        {
            check(a == 1);
            throw std::runtime_error("test exception");
        })
        .then([&]()
        {
            test.error("should not execute then() after a then() with exception");
            return;
        })
        .fail([&](const Error& err)
        {
            doneOrError(err.msg() == "test exception", );
        });
        pms.resolve(1);
    });
    asyncTest("Should fail with message if char* exception in then() block", {"fail"})
    {
        Promise<int> pms;
        pms.then([&](int a)
        {
            check(a == 1);
            throw "test char* exception";
        })
        .then([&]()
        {
            test.error("should not execute then() after a then() with exception");
            return;
        })
        .fail([&](const Error& err)
        {
            doneOrError(err.msg() == "test char* exception", "fail");
        });
        pms.resolve(1);
    });
    asyncTest("Should fail if non-std exception in then() block", {"fail"})
    {
        Promise<int> pms;
        pms.then([&](int a)
        {
            check(a == 1);
            throw 10;
        })
        .then([&]()
        {
            test.error("should not execute then() after a then() with exception");
            return;
        })
        .fail([&](const Error& err)
        {
            test.done("fail");
        });
        pms.resolve(1);
    });
    asyncTest("Should fail if exception in fail() block", {"fail", "fail excep"})
    {
        Promise<int> pms;
        pms.then([&](int)
        {
            test.error("Should not execute then() on failed promise");
        })
        .fail([&](const Error& err)
        {
            doneOrError(err.msg() == "test message", "fail");
            throw std::runtime_error("Test exception");
        })
        .fail([&](const Error& err)
        {
            doneOrError(err.msg() == "Test exception", "fail excep");
        });
        pms.reject("test message");
    });
});
TestGroup("Double resolve tests")
{
    asyncTest("Should throw if trying to resolve resolved promise", {"excep"})
    {
        Promise<int> pms;
        pms.resolve(1);
        check(pms.succeeded());
        try
        {
            pms.resolve(2);
        }
        catch(...)
        {
            test.done("excep");
        }
    });
    asyncTest("Should throw if trying to resolve failed promise", {"excep"})
    {
        Promise<int> pms;
        pms.reject("test error");
        check(pms.failed());
        try
        {
            pms.resolve(2);
        }
        catch(...)
        {
            test.done("excep");
        }
    });
    asyncTest("Should throw if trying to reject resolved promise", {"excep"})
    {
        Promise<int> pms;
        pms.resolve(1);
        check(pms.succeeded());
        try
        {
            pms.reject("test");
        }
        catch(...)
        {
            test.done("excep");
        }
    });
    asyncTest("Should throw if trying to reject a failed promise", {"excep"})
    {
        Promise<int> pms;
        pms.reject("test1");
        check(pms.failed());
        try
        {
            pms.reject("test2");
        }
        catch(...)
        {
            test.done("excep");
        }
    });

});

TestGroup("when() tests")
{
    asyncTest("when() with 2 already resolved promises")
    {
        Promise<int> pms1;
        pms1.resolve(1);
        Promise<void> pms2;
        pms2.resolve();
        when(pms1, pms2)
        .then([&]()
        {
            test.done();
        });
    });
    asyncTest("when() with 1 already-resolved and one async-resolved promise")
    {
        Promise<int> pms1;
        pms1.resolve(1);
        Promise<void> pms2;
        when(pms1, pms2)
        .then([&]()
        {
            test.done();
        });
        loop.schedCall([pms2]() mutable { pms2.resolve(); }, 100);
    });
    asyncTest("when() with 2 async-resolved promises")
    {
        Promise<int> pms1;
        Promise<void> pms2;
        when(pms1, pms2)
        .then([&]()
        {
            test.done();
        });
        loop.schedCall([pms1]() mutable { pms1.resolve(1); }, 100);
        loop.schedCall([pms2]() mutable { pms2.resolve(); }, 100);
    });
    asyncTest("when() with one already-failed and one async-resolved promise")
    {
        //when() should fail immediately without waiting for the unresolved promise
        Promise<void> pms1;
        pms1.reject("Test error message");
        Promise<int> pms2;
        when(pms1, pms2)
        .then([&]()
        {
            test.error("Rejected output promise must not call then()");
        })
        .fail([&](const Error& err)
        {
            doneOrError(err.msg() == "Test error message",);
        });
    });
    asyncTest("when() with one async-failed and one async-resolved promise",
    {{"first", "order", 1}, {"second", "order", 2}, {"output", "order", 3}})
    {
        Promise<void> pms1;
        Promise<int> pms2;
        when(pms1, pms2)
        .then([&]()
        {
            test.error("Rejected output promise must not call then()");
        })
        .fail([&](const Error& err)
        {
            doneOrError(err.msg() == "Test message", "output");
        });
        loop.schedCall([pms1, &test]() mutable { test.done("first"); pms1.resolve(); }, -100);
        loop.schedCall([pms2, &test]() mutable { test.done("second"); pms2.reject("Test message");}, -100);
    });
    asyncTest("when() with two already failed promises")
    {
        Promise<int> pms1(Error("first rejected"));
        Promise<void> pms2(Error("second rejected"));
        when(pms1, pms2)
        .then([&]()
        {
            test.error("Output should not succeed");
        })
        .fail([&](const Error& err)
        {
            doneOrError(err.msg() == "first rejected",);
        });
    });
    asyncTest("when() with four async-resolved promises",{
     {"first", "order", 1}, {"second", "order", 2}, {"third", "order", 3},
     {"fourth", "order", 4}, {"output", "order", 5}})
    {
        Promise<void> pms1;
        Promise<int> pms2;
        Promise<const char*> pms3;
        Promise<std::string> pms4;
        when(pms1, pms2, pms3, pms4)
        .then([&]()
        {
            test.done("output");
        })
        .fail([&](const Error& err)
        {
            test.error("Output promise should not fail()");
        });
        loop.schedCall([pms1, &test]() mutable { test.done("first"); pms1.resolve(); }, -100);
        loop.schedCall([pms2, &test]() mutable { test.done("second"); pms2.resolve(1);}, -100);
        loop.schedCall([pms3, &test]() mutable { test.done("third"); pms3.resolve("test"); }, -100);
        loop.schedCall([pms4, &test]() mutable { test.done("fourth"); pms4.resolve("test fourth"); }, -100);
    });
    asyncTest("when() with 3 async-resolved promises, and one async-failed",{
     {"first", "order", 1}, {"second", "order", 2}, {"third", "order", 3},
     {"fourth", "order", 4}, {"output", "order", 5}})
    {
        Promise<void> pms1;
        Promise<int> pms2;
        Promise<const char*> pms3;
        Promise<std::string> pms4;
        when(pms1, pms2, pms3, pms4)
        .then([&]()
        {
            test.error("Output promise should fail, not call then()");
        })
        .fail([&](const Error& err)
        {
            doneOrError(err.msg() == "test fourth fail", "output");
        });
        loop.schedCall([pms1, &test]() mutable { test.done("first"); pms1.resolve(); }, -100);
        loop.schedCall([pms2, &test]() mutable { test.done("second"); pms2.resolve(1);}, -100);
        loop.schedCall([pms3, &test]() mutable { test.done("third"); pms3.resolve("test"); }, -100);
        loop.schedCall([pms4, &test]() mutable { test.done("fourth"); pms4.reject("test fourth fail"); }, -100);
    });
    asyncTest("when() with array of promises, one failed", {"output"})
    {
        std::vector<Promise<int>> inputs(4);
        when(inputs)
        .then([&]()
        {
            test.error(("Output promise should fail, not call then()"));
        })
        .fail([&](const Error& err)
        {
            doneOrError(err.msg() == "test fourth fail", "output");
        });

        auto& in0 = inputs[0];
        auto& in1 = inputs[1];
        auto& in2 = inputs[2];
        auto& in3 = inputs[3];
        loop.schedCall([in0]() mutable { in0.resolve(10); }, -100);
        loop.schedCall([in1]() mutable { in1.resolve(20); }, -100);
        loop.schedCall([in2]() mutable { in2.resolve(30); }, -100);
        loop.schedCall([in3]() mutable { in3.reject("test fourth fail"); }, -100);
    });
});
TestGroup("Unhandled promise fail")
{
    asyncTest("Unhandled fail with async-rejected promise", {"unhandled"})
    {
        Promise<int> pms;
        pms.then([&test](int a)
        {
            test.error("Promise is rejected, should not reslove");
        });

        gUnhandledHandler = [&loop, &test](const std::string& msg, int type, int code)
        {
            doneOrError(msg == "test unhandled reported" && type == 1 && code == 2, "unhandled");
        };
        loop.schedCall([pms]() mutable { pms.reject("test unhandled reported", 2, 1);}, -100);
    });
    asyncTest("Unhandled fail with alredy rejected promise", {"unhandled"})
    {
        Promise<int> pms(Error("test unhandled reported", 2, 1));
        pms.then([&test](int a)
        {
            test.error("Promise is rejected, should not reslove");
        });

        gUnhandledHandler = [&loop, &test](const std::string& msg, int type, int code)
        {
            doneOrError(msg == "test unhandled reported" && type == 1 && code == 2, "unhandled");
        };
    });
    asyncTest("Unhandled fail should not be reported when errors are handled (already failed promise)", {"handled"})
    {
        Promise<int> pms(Error("test", 2, 1));
        pms.then([&test](int a)
        {
            test.error("Promise is rejected, should not reslove");
        })
        .fail([&test, &loop](const Error& err)
        {
            loop.schedCall([&test]() { test.done("handled"); }, -100);
        });

        gUnhandledHandler = [&loop, &test](const std::string& msg, int type, int code)
        {
            test.error("unhandled error reported");
        };
    });
    asyncTest("Unhandled fail should not be reported when errors are handled (async failed promise)", {"handled"})
    {
        Promise<int> pms;
        pms.then([&test](int a)
        {
            test.error("Promise is rejected, should not reslove");
        })
        .fail([&test, &loop](const Error& err)
        {
            loop.schedCall([&test]() { test.done("handled"); }, -100);
        });

        gUnhandledHandler = [&loop, &test](const std::string& msg, int type, int code)
        {
            test.error("unhandled error reported");
        };
        loop.schedCall([pms]() mutable { pms.reject("test"); });
    });
});

return test::gNumFailed;
}
